INFO: 2025-01-19 23:28:07,703: main() 'Using profile folder /home/marc/.config/variety/'
INFO: 2025-01-19 23:28:08,642: perform_upgrade() 'Last run version was 0.8.12 or earlier, current version is 0.8.12'
INFO: 2025-01-19 23:28:08,776: process_command() 'Received command: []'
INFO: 2025-01-19 23:28:08,780: start() 'Using data_path /nix/store/xc3xswijz8h0ccdq73257z072m37phnq-variety-0.8.12/share/variety'
INFO: 2025-01-19 23:28:08,780: load() 'Jumble loading'
INFO: 2025-01-19 23:28:08,780: _walk_modules() 'Jumble loading module in __init__ from /nix/store/xc3xswijz8h0ccdq73257z072m37phnq-variety-0.8.12/lib/python3.12/site-packages/variety/plugins/builtin/__init__.py'
INFO: 2025-01-19 23:28:08,781: _walk_modules() 'Jumble loading module in GnomeDisplayModesPlugin from /nix/store/xc3xswijz8h0ccdq73257z072m37phnq-variety-0.8.12/lib/python3.12/site-packages/variety/plugins/builtin/display_modes/GnomeDisplayModesPlugin.py'
INFO: 2025-01-19 23:28:08,782: load() 'Jumble found plugin class: <class 'GnomeDisplayModesPlugin.GnomeDisplayModesPlugin'>: {'name': 'GnomeDisplayModesPlugin', 'description': 'Display modes relying on the underlying desktop environment', 'version': '1.0', 'author': 'Peter Levi'}'
INFO: 2025-01-19 23:28:08,782: _walk_modules() 'Jumble loading module in LegacyDisplayModesPlugin from /nix/store/xc3xswijz8h0ccdq73257z072m37phnq-variety-0.8.12/lib/python3.12/site-packages/variety/plugins/builtin/display_modes/LegacyDisplayModesPlugin.py'
INFO: 2025-01-19 23:28:08,782: load() 'Jumble found plugin class: <class 'LegacyDisplayModesPlugin.LegacyDisplayModesPlugin'>: {'name': 'LegacyDisplayModesPlugin', 'description': 'Legacy display mode for compatibility with past Variety versions', 'version': '1.0', 'author': 'Peter Levi'}'
INFO: 2025-01-19 23:28:08,783: _walk_modules() 'Jumble loading module in ResizingDisplayModesPlugin from /nix/store/xc3xswijz8h0ccdq73257z072m37phnq-variety-0.8.12/lib/python3.12/site-packages/variety/plugins/builtin/display_modes/ResizingDisplayModesPlugin.py'
INFO: 2025-01-19 23:28:08,784: load() 'Jumble found plugin class: <class 'ResizingDisplayModesPlugin.ResizingDisplayModesPlugin'>: {'name': 'ResizingDisplayModesPlugin', 'description': 'Display modes that use image resizing within Variety', 'version': '1.0', 'author': 'Peter Levi'}'
INFO: 2025-01-19 23:28:08,784: _walk_modules() 'Jumble loading module in __init__ from /nix/store/xc3xswijz8h0ccdq73257z072m37phnq-variety-0.8.12/lib/python3.12/site-packages/variety/plugins/builtin/display_modes/__init__.py'
INFO: 2025-01-19 23:28:08,784: _walk_modules() 'Jumble loading module in APODDownloader from /nix/store/xc3xswijz8h0ccdq73257z072m37phnq-variety-0.8.12/lib/python3.12/site-packages/variety/plugins/builtin/downloaders/APODDownloader.py'
INFO: 2025-01-19 23:28:08,786: load() 'Jumble found plugin class: <class 'APODDownloader.APODDownloader'>: {'name': 'APODDownloader', 'description': 'NASA Astro Pic of the Day', 'author': 'Peter Levi', 'version': '0.1'}'
INFO: 2025-01-19 23:28:08,786: _walk_modules() 'Jumble loading module in ArtStationDownloader from /nix/store/xc3xswijz8h0ccdq73257z072m37phnq-variety-0.8.12/lib/python3.12/site-packages/variety/plugins/builtin/downloaders/ArtStationDownloader.py'
INFO: 2025-01-19 23:28:08,787: _walk_modules() 'Jumble loading module in ArtStationSource from /nix/store/xc3xswijz8h0ccdq73257z072m37phnq-variety-0.8.12/lib/python3.12/site-packages/variety/plugins/builtin/downloaders/ArtStationSource.py'
INFO: 2025-01-19 23:28:08,789: load() 'Jumble found plugin class: <class 'ArtStationSource.ArtStationSource'>: {'name': 'ArtStationSource', 'description': 'Configurable source for fetching images from ArtStation', 'author': 'Denis Gordeev', 'version': '0.1'}'
INFO: 2025-01-19 23:28:08,790: _walk_modules() 'Jumble loading module in BingDownloader from /nix/store/xc3xswijz8h0ccdq73257z072m37phnq-variety-0.8.12/lib/python3.12/site-packages/variety/plugins/builtin/downloaders/BingDownloader.py'
INFO: 2025-01-19 23:28:08,791: load() 'Jumble found plugin class: <class 'BingDownloader.BingDownloader'>: {'name': 'BingDownloader', 'description': 'Bing Photo of the Day', 'author': 'Peter Levi', 'version': '0.1'}'
INFO: 2025-01-19 23:28:08,791: _walk_modules() 'Jumble loading module in EarthviewDownloader from /nix/store/xc3xswijz8h0ccdq73257z072m37phnq-variety-0.8.12/lib/python3.12/site-packages/variety/plugins/builtin/downloaders/EarthviewDownloader.py'
INFO: 2025-01-19 23:28:08,792: load() 'Jumble found plugin class: <class 'EarthviewDownloader.EarthviewDownloader'>: {'name': 'EarthviewDownloader', 'description': 'Google Earth View Wallpapers', 'author': 'Peter Levi', 'version': '0.1'}'
INFO: 2025-01-19 23:28:08,792: _walk_modules() 'Jumble loading module in MediaRSSDownloader from /nix/store/xc3xswijz8h0ccdq73257z072m37phnq-variety-0.8.12/lib/python3.12/site-packages/variety/plugins/builtin/downloaders/MediaRSSDownloader.py'
INFO: 2025-01-19 23:28:08,794: _walk_modules() 'Jumble loading module in MediaRSSSource from /nix/store/xc3xswijz8h0ccdq73257z072m37phnq-variety-0.8.12/lib/python3.12/site-packages/variety/plugins/builtin/downloaders/MediaRSSSource.py'
INFO: 2025-01-19 23:28:08,796: load() 'Jumble found plugin class: <class 'MediaRSSSource.MediaRSSSource'>: {'name': 'MediaRSSSource', 'description': 'Configurable source for fetching images from MediaRSS feeds', 'author': 'Peter Levi', 'version': '0.1'}'
INFO: 2025-01-19 23:28:08,796: _walk_modules() 'Jumble loading module in NationalGeographicDownloader from /nix/store/xc3xswijz8h0ccdq73257z072m37phnq-variety-0.8.12/lib/python3.12/site-packages/variety/plugins/builtin/downloaders/NationalGeographicDownloader.py'
INFO: 2025-01-19 23:28:08,798: load() 'Jumble found plugin class: <class 'NationalGeographicDownloader.NationalGeographicDownloader'>: {'name': 'NationalGeographicDownloader', 'description': "National Geographic's photo of the day", 'author': 'Eric RÃ¶sch', 'version': '0.1'}'
INFO: 2025-01-19 23:28:08,798: _walk_modules() 'Jumble loading module in RedditDownloader from /nix/store/xc3xswijz8h0ccdq73257z072m37phnq-variety-0.8.12/lib/python3.12/site-packages/variety/plugins/builtin/downloaders/RedditDownloader.py'
INFO: 2025-01-19 23:28:08,799: _walk_modules() 'Jumble loading module in RedditSource from /nix/store/xc3xswijz8h0ccdq73257z072m37phnq-variety-0.8.12/lib/python3.12/site-packages/variety/plugins/builtin/downloaders/RedditSource.py'
INFO: 2025-01-19 23:28:08,802: load() 'Jumble found plugin class: <class 'RedditSource.RedditSource'>: {'name': 'RedditSource', 'description': 'Configurable source for fetching images from Reddit', 'author': 'Peter Levi', 'version': '0.1'}'
INFO: 2025-01-19 23:28:08,802: _walk_modules() 'Jumble loading module in UnsplashConfigurableSource from /nix/store/xc3xswijz8h0ccdq73257z072m37phnq-variety-0.8.12/lib/python3.12/site-packages/variety/plugins/builtin/downloaders/UnsplashConfigurableSource.py'
INFO: 2025-01-19 23:28:08,804: load() 'Jumble found plugin class: <class 'UnsplashConfigurableSource.UnsplashConfigurableSource'>: {'name': 'UnsplashConfigurableSource', 'description': 'Configurable source for fetching photos from Unsplash.com', 'author': 'Peter Levi', 'version': '0.1'}'
INFO: 2025-01-19 23:28:08,804: _walk_modules() 'Jumble loading module in UnsplashDownloader from /nix/store/xc3xswijz8h0ccdq73257z072m37phnq-variety-0.8.12/lib/python3.12/site-packages/variety/plugins/builtin/downloaders/UnsplashDownloader.py'
INFO: 2025-01-19 23:28:08,805: load() 'Jumble found plugin class: <class 'UnsplashDownloader.UnsplashDownloader'>: {'name': 'UnsplashDownloader', 'description': 'High-resolution photos from Unsplash.com', 'author': 'Peter Levi', 'version': '0.1'}'
INFO: 2025-01-19 23:28:08,805: _walk_modules() 'Jumble loading module in WallhavenDownloader from /nix/store/xc3xswijz8h0ccdq73257z072m37phnq-variety-0.8.12/lib/python3.12/site-packages/variety/plugins/builtin/downloaders/WallhavenDownloader.py'
INFO: 2025-01-19 23:28:08,807: _walk_modules() 'Jumble loading module in WallhavenLegacyDownloader from /nix/store/xc3xswijz8h0ccdq73257z072m37phnq-variety-0.8.12/lib/python3.12/site-packages/variety/plugins/builtin/downloaders/WallhavenLegacyDownloader.py'
INFO: 2025-01-19 23:28:08,808: _walk_modules() 'Jumble loading module in WallhavenSource from /nix/store/xc3xswijz8h0ccdq73257z072m37phnq-variety-0.8.12/lib/python3.12/site-packages/variety/plugins/builtin/downloaders/WallhavenSource.py'
INFO: 2025-01-19 23:28:08,810: load() 'Jumble found plugin class: <class 'WallhavenSource.WallhavenSource'>: {'name': 'WallhavenSource', 'description': 'Configurable source for fetching images from Wallhaven.cc', 'author': 'Peter Levi', 'version': '0.1'}'
INFO: 2025-01-19 23:28:08,810: _walk_modules() 'Jumble loading module in __init__ from /nix/store/xc3xswijz8h0ccdq73257z072m37phnq-variety-0.8.12/lib/python3.12/site-packages/variety/plugins/builtin/downloaders/__init__.py'
INFO: 2025-01-19 23:28:08,810: _walk_modules() 'Jumble loading module in FortuneSource from /nix/store/xc3xswijz8h0ccdq73257z072m37phnq-variety-0.8.12/lib/python3.12/site-packages/variety/plugins/builtin/quotes/FortuneSource.py'
INFO: 2025-01-19 23:28:08,811: load() 'Jumble found plugin class: <class 'FortuneSource.FortuneSource'>: {'name': 'UNIX fortune program', 'description': 'Displays quotes using the UNIX fortune program. You may want to install additional fortune packs, e.g. fortunes-bofh-excuses.', 'author': 'Dan Jones', 'version': '0.1'}'
INFO: 2025-01-19 23:28:08,812: _walk_modules() 'Jumble loading module in GoodreadsSource from /nix/store/xc3xswijz8h0ccdq73257z072m37phnq-variety-0.8.12/lib/python3.12/site-packages/variety/plugins/builtin/quotes/GoodreadsSource.py'
INFO: 2025-01-19 23:28:08,881: load() 'Jumble found plugin class: <class 'GoodreadsSource.GoodreadsSource'>: {'name': 'Goodreads', 'description': 'Fetches quotes from Goodreads.com', 'author': 'Peter Levi', 'version': '0.1'}'
INFO: 2025-01-19 23:28:08,881: _walk_modules() 'Jumble loading module in LocalFilesSource from /nix/store/xc3xswijz8h0ccdq73257z072m37phnq-variety-0.8.12/lib/python3.12/site-packages/variety/plugins/builtin/quotes/LocalFilesSource.py'
INFO: 2025-01-19 23:28:08,883: load() 'Jumble found plugin class: <class 'LocalFilesSource.LocalFilesSource'>: {'name': 'Local text files', 'description': 'Displays quotes, defined in local text files.\nPut your own txt files in: ~/.config/variety/pluginconfig/quotes/.\nThe file format is:\n\nquote -- author\n.\nsecond quote -- another author\n.\netc...\n\nExample: http://rvelthuis.de/zips/quotes.txt', 'author': 'Peter Levi', 'version': '0.1'}'
INFO: 2025-01-19 23:28:08,883: _walk_modules() 'Jumble loading module in QuotationsPageSource from /nix/store/xc3xswijz8h0ccdq73257z072m37phnq-variety-0.8.12/lib/python3.12/site-packages/variety/plugins/builtin/quotes/QuotationsPageSource.py'
INFO: 2025-01-19 23:28:08,884: load() 'Jumble found plugin class: <class 'QuotationsPageSource.QuotationsPageSource'>: {'name': 'TheQuotationsPage.com', 'description': 'Fetches quotes from TheQuotationsPage.com', 'author': 'Peter Levi', 'version': '0.1'}'
INFO: 2025-01-19 23:28:08,885: _walk_modules() 'Jumble loading module in UrbanDictionarySource from /nix/store/xc3xswijz8h0ccdq73257z072m37phnq-variety-0.8.12/lib/python3.12/site-packages/variety/plugins/builtin/quotes/UrbanDictionarySource.py'
INFO: 2025-01-19 23:28:08,885: load() 'Jumble found plugin class: <class 'UrbanDictionarySource.UrbanDictionarySource'>: {'name': 'Urban Dictionary', 'description': 'Displays definitions from Urban Dictionary', 'author': 'James Miller', 'version': '0.1'}'
INFO: 2025-01-19 23:28:08,886: _walk_modules() 'Jumble loading module in __init__ from /nix/store/xc3xswijz8h0ccdq73257z072m37phnq-variety-0.8.12/lib/python3.12/site-packages/variety/plugins/builtin/quotes/__init__.py'
INFO: 2025-01-19 23:28:09,175: reload_config() 'Creating new downloader for type unsplash, location High-resolution photos from Unsplash.com'
INFO: 2025-01-19 23:28:09,204: log_options() 'Loaded options:'
INFO: 2025-01-19 23:28:09,205: log_options() 'change_enabled = False'
INFO: 2025-01-19 23:28:09,205: log_options() 'change_interval = 300'
INFO: 2025-01-19 23:28:09,205: log_options() 'change_on_start = False'
INFO: 2025-01-19 23:28:09,205: log_options() 'clipboard_enabled = False'
INFO: 2025-01-19 23:28:09,205: log_options() 'clipboard_hosts = ['wallhaven.cc', 'wallpapers.net', 'flickr.com', 'imgur.com', 'deviantart.com', 'interfacelift.com', 'vladstudio.com', 'imageshack.us', 'deviantart.net', 'imageshack.com']'
INFO: 2025-01-19 23:28:09,205: log_options() 'clipboard_use_whitelist = True'
INFO: 2025-01-19 23:28:09,205: log_options() 'clock_date_font = Serif 30'
INFO: 2025-01-19 23:28:09,206: log_options() 'clock_enabled = False'
INFO: 2025-01-19 23:28:09,206: log_options() 'clock_filter = -density 100 -font `fc-match -f '%{file[0]}' '%CLOCK_FONT_NAME'` -pointsize %CLOCK_FONT_SIZE -gravity SouthEast -fill '#00000044' -annotate 0x0+[%HOFFSET+58]+[%VOFFSET+108] '%H:%M' -fill white -annotate 0x0+[%HOFFSET+60]+[%VOFFSET+110] '%H:%M' -font `fc-match -f '%{file[0]}' '%DATE_FONT_NAME'` -pointsize %DATE_FONT_SIZE -fill '#00000044' -annotate 0x0+[%HOFFSET+58]+[%VOFFSET+58] '%A, %B %d' -fill white -annotate 0x0+[%HOFFSET+60]+[%VOFFSET+60] '%A, %B %d''
INFO: 2025-01-19 23:28:09,206: log_options() 'clock_font = Serif 70'
INFO: 2025-01-19 23:28:09,206: log_options() 'configfile = /home/marc/.config/variety/variety.conf'
INFO: 2025-01-19 23:28:09,206: log_options() 'copyto_enabled = True'
INFO: 2025-01-19 23:28:09,206: log_options() 'copyto_folder = Default'
INFO: 2025-01-19 23:28:09,206: log_options() 'desired_color = [160, 160, 160]'
INFO: 2025-01-19 23:28:09,206: log_options() 'desired_color_enabled = False'
INFO: 2025-01-19 23:28:09,206: log_options() 'download_folder = /home/marc/.config/variety/Downloaded'
INFO: 2025-01-19 23:28:09,207: log_options() 'download_preference_ratio = 0.9'
INFO: 2025-01-19 23:28:09,207: log_options() 'favorites_folder = /home/marc/.config/variety/Favorites'
INFO: 2025-01-19 23:28:09,207: log_options() 'favorites_operations = [['Downloaded', 'Copy'], ['Fetched', 'Move'], ['Others', 'Copy']]'
INFO: 2025-01-19 23:28:09,207: log_options() 'fetched_folder = /home/marc/.config/variety/Fetched'
INFO: 2025-01-19 23:28:09,207: log_options() 'filters = [[False, 'Keep original', ''], [False, 'Grayscale', '-type Grayscale'], [False, 'Heavy blur', '-scale 20% -blur 0x10 -resize 500%'], [False, 'Soft blur', '-scale 20% -blur 0x2 -resize 500%'], [False, 'Oil painting', '-paint 8'], [False, 'Pointilism', '-spread 10 -noise 3'], [False, 'Pixellate', '-scale 3% -scale 3333%']]'
INFO: 2025-01-19 23:28:09,207: log_options() 'get_wallpaper_script = /home/marc/.config/variety/scripts/get_wallpaper'
INFO: 2025-01-19 23:28:09,207: log_options() 'icon = Dark'
INFO: 2025-01-19 23:28:09,207: log_options() 'internet_enabled = True'
INFO: 2025-01-19 23:28:09,207: log_options() 'lightness_enabled = False'
INFO: 2025-01-19 23:28:09,208: log_options() 'lightness_mode = 0'
INFO: 2025-01-19 23:28:09,208: log_options() 'min_rating = 4'
INFO: 2025-01-19 23:28:09,208: log_options() 'min_rating_enabled = False'
INFO: 2025-01-19 23:28:09,208: log_options() 'min_size = 80'
INFO: 2025-01-19 23:28:09,208: log_options() 'min_size_enabled = False'
INFO: 2025-01-19 23:28:09,208: log_options() 'quota_enabled = True'
INFO: 2025-01-19 23:28:09,208: log_options() 'quota_size = 1000'
INFO: 2025-01-19 23:28:09,208: log_options() 'quotes_authors = '
INFO: 2025-01-19 23:28:09,208: log_options() 'quotes_bg_color = [80, 80, 80]'
INFO: 2025-01-19 23:28:09,208: log_options() 'quotes_bg_opacity = 55'
INFO: 2025-01-19 23:28:09,209: log_options() 'quotes_change_enabled = False'
INFO: 2025-01-19 23:28:09,209: log_options() 'quotes_change_interval = 300'
INFO: 2025-01-19 23:28:09,209: log_options() 'quotes_disabled_sources = ['Urban Dictionary']'
INFO: 2025-01-19 23:28:09,209: log_options() 'quotes_enabled = False'
INFO: 2025-01-19 23:28:09,209: log_options() 'quotes_favorites_file = /home/marc/.config/variety/favorite_quotes.txt'
INFO: 2025-01-19 23:28:09,209: log_options() 'quotes_font = Serif 30'
INFO: 2025-01-19 23:28:09,209: log_options() 'quotes_hpos = 100'
INFO: 2025-01-19 23:28:09,209: log_options() 'quotes_max_length = 250'
INFO: 2025-01-19 23:28:09,209: log_options() 'quotes_tags = '
INFO: 2025-01-19 23:28:09,210: log_options() 'quotes_text_color = [255, 255, 255]'
INFO: 2025-01-19 23:28:09,210: log_options() 'quotes_text_shadow = False'
INFO: 2025-01-19 23:28:09,210: log_options() 'quotes_vpos = 40'
INFO: 2025-01-19 23:28:09,210: log_options() 'quotes_width = 70'
INFO: 2025-01-19 23:28:09,210: log_options() 'safe_mode = False'
INFO: 2025-01-19 23:28:09,210: log_options() 'set_wallpaper_script = /home/marc/.config/variety/scripts/set_wallpaper'
INFO: 2025-01-19 23:28:09,210: log_options() 'slideshow_custom_enabled = False'
INFO: 2025-01-19 23:28:09,210: log_options() 'slideshow_custom_folder = /home/marc/Pictures'
INFO: 2025-01-19 23:28:09,210: log_options() 'slideshow_downloads_enabled = False'
INFO: 2025-01-19 23:28:09,211: log_options() 'slideshow_fade = 0.4'
INFO: 2025-01-19 23:28:09,211: log_options() 'slideshow_favorites_enabled = True'
INFO: 2025-01-19 23:28:09,211: log_options() 'slideshow_mode = Fullscreen'
INFO: 2025-01-19 23:28:09,211: log_options() 'slideshow_monitor = All'
INFO: 2025-01-19 23:28:09,211: log_options() 'slideshow_pan = 0.05'
INFO: 2025-01-19 23:28:09,211: log_options() 'slideshow_seconds = 6.0'
INFO: 2025-01-19 23:28:09,211: log_options() 'slideshow_sort_order = Random'
INFO: 2025-01-19 23:28:09,211: log_options() 'slideshow_sources_enabled = True'
INFO: 2025-01-19 23:28:09,211: log_options() 'slideshow_zoom = 0.2'
INFO: 2025-01-19 23:28:09,212: log_options() 'smart_enabled = False'
INFO: 2025-01-19 23:28:09,212: log_options() 'smart_notice_shown = False'
INFO: 2025-01-19 23:28:09,212: log_options() 'smart_register_shown = False'
INFO: 2025-01-19 23:28:09,212: log_options() 'sources = [[False, 'favorites', 'The Favorites folder'], [False, 'fetched', 'The Fetched folder'], [False, 'folder', '/usr/share/backgrounds'], [False, 'flickr', 'user:www.flickr.com/photos/peter-levi/;user_id:93647178@N00;'], [False, 'apod', "NASA's Astronomy Picture of the Day"], [False, 'bing', 'Bing Photo of the Day'], [False, 'earthview', 'Google Earth View Wallpapers'], [False, 'natgeo', "National Geographic's photo of the day"], [True, 'unsplash', 'High-resolution photos from Unsplash.com'], [False, 'folder', '/mnt/storage/pictures/celebrities'], [False, 'folder', '/mnt/storage/pictures'], [False, 'folder', '/mnt/storage/pictures/linux'], [False, 'folder', '/mnt/storage/pictures/new-pool'], [False, 'folder', '/mnt/storage/pictures/solid-colors'], [False, 'folder', '/mnt/storage/pictures/cities-towns'], [False, 'folder', '/mnt/storage/pictures/blue-sea'], [True, 'folder', '/mnt/storage/pictures/shows-broadcasts'], [True, 'folder', '/home/marc/Downloads'], [True, 'folder', '/mnt/storage/pictures/anime'], [True, 'folder', '/mnt/storage/pictures/kde-images'], [True, 'folder', '/mnt/storage/pictures/nature'], [True, 'folder', '/mnt/storage/documents/websites/makc wallpapers/wallpapers/art'], [True, 'image', '/mnt/storage/pictures/101808.jpg']]'
INFO: 2025-01-19 23:28:09,212: log_options() 'stats_enabled = True'
INFO: 2025-01-19 23:28:09,212: log_options() 'stats_notice_shown = False'
INFO: 2025-01-19 23:28:09,212: log_options() 'sync_enabled = True'
INFO: 2025-01-19 23:28:09,212: log_options() 'use_landscape_enabled = True'
INFO: 2025-01-19 23:28:09,212: log_options() 'wallhaven_api_key = '
INFO: 2025-01-19 23:28:09,213: log_options() 'wallpaper_auto_rotate = False'
INFO: 2025-01-19 23:28:09,213: log_options() 'wallpaper_display_mode = os'
INFO: 2025-01-19 23:28:09,213: reload_config() 'No need to clear prepared queue'
INFO: 2025-01-19 23:28:09,213: update_indicator() 'Setting file info to: /mnt/storage/pictures/linux/Photo-of-Valley.jpg'
INFO: 2025-01-19 23:28:09,214: load_banned() 'Missing or invalid banned URLs list, no URLs will be banned'
INFO: 2025-01-19 23:28:09,214: load_last_change_time() 'Change interval < 6 hours, ignore persisted last_change_time, wait initially the whole interval: 300'
INFO: 2025-01-19 23:28:09,214: update_indicator() 'Setting file info to: /mnt/storage/pictures/linux/Photo-of-Valley.jpg'
INFO: 2025-01-19 23:28:09,215: regular_change_thread() 'regular_change thread running'
INFO: 2025-01-19 23:28:09,216: regular_change_thread() 'regular_change: waiting till user resumes'
INFO: 2025-01-19 23:28:09,216: prepare_thread() 'Prepare thread running'
INFO: 2025-01-19 23:28:09,217: prepare_thread() 'Prepared buffer contains 0 images'
INFO: 2025-01-19 23:28:09,218: prepare_thread() 'Preparing some images'
INFO: 2025-01-19 23:28:09,222: update_indicator_icon() 'Creating indicator'
WARNING: 2025-01-19 23:28:09,292: create_menu() 'Variety Slideshow is not installed. This is an optional extension adding pan-and-zoom slideshows to Variety: see https://github.com/peterlevi/variety-slideshow for details'
INFO: 2025-01-19 23:28:09,293: create_indicator() 'indicator backend: AyatanaAppIndicator3'
INFO: 2025-01-19 23:28:09,313: set_from_theme_icon() 'Showing indicator icon variety-indicator-dark from GTK theme'
INFO: 2025-01-19 23:28:09,314: do_set_wp() 'Calling do_set_wp with /mnt/storage/pictures/linux/Photo-of-Valley.jpg, time: 1737322089.3145592'
INFO: 2025-01-19 23:28:09,554: update_indicator() 'Setting file info to: /mnt/storage/pictures/linux/Photo-of-Valley.jpg'
INFO: 2025-01-19 23:28:09,571: list_files() 'More than 1 files in the folders, stop listing'
WARNING: 2025-01-19 23:28:09,703: image_ok() 'Error in image_ok for file /mnt/storage/pictures/kde-images/F39/contents/images_dark/1920x1440.png'
WARNING: 2025-01-19 23:28:09,703: image_ok() 'Error in image_ok for file /mnt/storage/pictures/kde-images/Fedora/contents/images_dark/2048x1536.png'
WARNING: 2025-01-19 23:28:09,775: image_ok() 'Error in image_ok for file /mnt/storage/pictures/kde-images/F40/contents/images_dark/800x600.png'
WARNING: 2025-01-19 23:28:09,868: image_ok() 'Error in image_ok for file /mnt/storage/pictures/kde-images/F39/contents/images_dark/1680x1050.png'
WARNING: 2025-01-19 23:28:09,868: image_ok() 'Error in image_ok for file /mnt/storage/pictures/kde-images/Fedora/contents/images/1280x960.png'
WARNING: 2025-01-19 23:28:09,891: image_ok() 'Error in image_ok for file /mnt/storage/pictures/kde-images/Fedora/contents/images_dark/1366x768.png'
WARNING: 2025-01-19 23:28:09,903: image_ok() 'Error in image_ok for file /mnt/storage/pictures/kde-images/F39/contents/images/1152x864.png'
WARNING: 2025-01-19 23:28:09,932: image_ok() 'Error in image_ok for file /mnt/storage/pictures/kde-images/F39/contents/images/1680x1050.png'
WARNING: 2025-01-19 23:28:10,005: image_ok() 'Error in image_ok for file /mnt/storage/pictures/kde-images/F39/contents/images_dark/3200x1800.png'
WARNING: 2025-01-19 23:28:10,126: image_ok() 'Error in image_ok for file /mnt/storage/pictures/kde-images/F40/contents/images_dark/2048x1536.png'
WARNING: 2025-01-19 23:28:10,311: image_ok() 'Error in image_ok for file /mnt/storage/pictures/kde-images/F39/contents/images/2160x1440.png'
WARNING: 2025-01-19 23:28:10,311: image_ok() 'Error in image_ok for file /mnt/storage/pictures/kde-images/Fedora/contents/images_dark/1920x1280.png'
WARNING: 2025-01-19 23:28:10,536: image_ok() 'Error in image_ok for file /mnt/storage/pictures/kde-images/F40/contents/images/800x480.png'
WARNING: 2025-01-19 23:28:10,542: image_ok() 'Error in image_ok for file /mnt/storage/pictures/kde-images/F40/contents/images_dark/2960x1440.png'
INFO: 2025-01-19 23:28:10,557: reload() 'Reloading preferences dialog'
WARNING: 2025-01-19 23:28:10,583: image_ok() 'Error in image_ok for file /mnt/storage/pictures/kde-images/F40/contents/images/640x480.png'
WARNING: 2025-01-19 23:28:10,613: image_ok() 'Error in image_ok for file /mnt/storage/pictures/kde-images/F39/contents/images/1280x720.png'
WARNING: 2025-01-19 23:28:10,705: image_ok() 'Error in image_ok for file /mnt/storage/pictures/kde-images/Fedora/contents/images/1200x900.png'
WARNING: 2025-01-19 23:28:10,708: image_ok() 'Error in image_ok for file /mnt/storage/pictures/kde-images/F39/contents/images/1920x1080.png'
WARNING: 2025-01-19 23:28:10,709: image_ok() 'Error in image_ok for file /mnt/storage/pictures/kde-images/Fedora/contents/images/2304x1440.png'
WARNING: 2025-01-19 23:28:10,709: image_ok() 'Error in image_ok for file /mnt/storage/pictures/kde-images/F39/contents/images/3840x2160.png'
WARNING: 2025-01-19 23:28:10,730: image_ok() 'Error in image_ok for file /mnt/storage/pictures/kde-images/F40/contents/images_dark/1280x1024.png'
WARNING: 2025-01-19 23:28:10,832: image_ok() 'Error in image_ok for file /mnt/storage/pictures/kde-images/Fedora/contents/images/1366x768.png'
WARNING: 2025-01-19 23:28:10,867: image_ok() 'Error in image_ok for file /mnt/storage/pictures/kde-images/Fedora/contents/images_dark/2160x1440.png'
INFO: 2025-01-19 23:28:10,914: prepare_thread() 'After search prepared buffer contains 74 images'
INFO: 2025-01-19 23:28:12,915: trigger_download() 'Triggering download thread to check if download needed and possible'
INFO: 2025-01-19 23:28:29,219: server_options_thread() 'Fetching server options from http://tiny.cc/variety-options-063'
ERROR: 2025-01-19 23:28:29,236: server_options_thread() 'Could not fetch Variety serverside options'
Traceback (most recent call last):
  File "/nix/store/avkdkdhnb136l7scx4bnhjmnycfbjsl0-python3.12-urllib3-2.2.3/lib/python3.12/site-packages/urllib3/connection.py", line 199, in _new_conn
    sock = connection.create_connection(
           ^^^^^^^^^^^^^^^^^^^^^^^^^^^^^
  File "/nix/store/avkdkdhnb136l7scx4bnhjmnycfbjsl0-python3.12-urllib3-2.2.3/lib/python3.12/site-packages/urllib3/util/connection.py", line 60, in create_connection
    for res in socket.getaddrinfo(host, port, family, socket.SOCK_STREAM):
               ^^^^^^^^^^^^^^^^^^^^^^^^^^^^^^^^^^^^^^^^^^^^^^^^^^^^^^^^^^
  File "/nix/store/901c80rlps5q05bnjk1sj4zaz5k736nc-python3-3.12.7/lib/python3.12/socket.py", line 976, in getaddrinfo
    for res in _socket.getaddrinfo(host, port, family, type, proto, flags):
               ^^^^^^^^^^^^^^^^^^^^^^^^^^^^^^^^^^^^^^^^^^^^^^^^^^^^^^^^^^^
socket.gaierror: [Errno -3] Temporary failure in name resolution

The above exception was the direct cause of the following exception:

Traceback (most recent call last):
  File "/nix/store/avkdkdhnb136l7scx4bnhjmnycfbjsl0-python3.12-urllib3-2.2.3/lib/python3.12/site-packages/urllib3/connectionpool.py", line 789, in urlopen
    response = self._make_request(
               ^^^^^^^^^^^^^^^^^^^
  File "/nix/store/avkdkdhnb136l7scx4bnhjmnycfbjsl0-python3.12-urllib3-2.2.3/lib/python3.12/site-packages/urllib3/connectionpool.py", line 495, in _make_request
    conn.request(
  File "/nix/store/avkdkdhnb136l7scx4bnhjmnycfbjsl0-python3.12-urllib3-2.2.3/lib/python3.12/site-packages/urllib3/connection.py", line 441, in request
    self.endheaders()
  File "/nix/store/901c80rlps5q05bnjk1sj4zaz5k736nc-python3-3.12.7/lib/python3.12/http/client.py", line 1331, in endheaders
    self._send_output(message_body, encode_chunked=encode_chunked)
  File "/nix/store/901c80rlps5q05bnjk1sj4zaz5k736nc-python3-3.12.7/lib/python3.12/http/client.py", line 1091, in _send_output
    self.send(msg)
  File "/nix/store/901c80rlps5q05bnjk1sj4zaz5k736nc-python3-3.12.7/lib/python3.12/http/client.py", line 1035, in send
    self.connect()
  File "/nix/store/avkdkdhnb136l7scx4bnhjmnycfbjsl0-python3.12-urllib3-2.2.3/lib/python3.12/site-packages/urllib3/connection.py", line 279, in connect
    self.sock = self._new_conn()
                ^^^^^^^^^^^^^^^^
  File "/nix/store/avkdkdhnb136l7scx4bnhjmnycfbjsl0-python3.12-urllib3-2.2.3/lib/python3.12/site-packages/urllib3/connection.py", line 206, in _new_conn
    raise NameResolutionError(self.host, self, e) from e
urllib3.exceptions.NameResolutionError: <urllib3.connection.HTTPConnection object at 0x7fa448541dc0>: Failed to resolve 'tiny.cc' ([Errno -3] Temporary failure in name resolution)

The above exception was the direct cause of the following exception:

Traceback (most recent call last):
  File "/nix/store/l4y7mm2d1dnybyym01b4032h4gji221p-python3.12-requests-2.32.3/lib/python3.12/site-packages/requests/adapters.py", line 683, in send
    resp = conn.urlopen(
           ^^^^^^^^^^^^^
  File "/nix/store/avkdkdhnb136l7scx4bnhjmnycfbjsl0-python3.12-urllib3-2.2.3/lib/python3.12/site-packages/urllib3/connectionpool.py", line 843, in urlopen
    retries = retries.increment(
              ^^^^^^^^^^^^^^^^^^
  File "/nix/store/avkdkdhnb136l7scx4bnhjmnycfbjsl0-python3.12-urllib3-2.2.3/lib/python3.12/site-packages/urllib3/util/retry.py", line 519, in increment
    raise MaxRetryError(_pool, url, reason) from reason  # type: ignore[arg-type]
    ^^^^^^^^^^^^^^^^^^^^^^^^^^^^^^^^^^^^^^^^^^^^^^^^^^^
urllib3.exceptions.MaxRetryError: HTTPConnectionPool(host='tiny.cc', port=80): Max retries exceeded with url: /variety-options-063 (Caused by NameResolutionError("<urllib3.connection.HTTPConnection object at 0x7fa448541dc0>: Failed to resolve 'tiny.cc' ([Errno -3] Temporary failure in name resolution)"))

During handling of the above exception, another exception occurred:

Traceback (most recent call last):
  File "/nix/store/xc3xswijz8h0ccdq73257z072m37phnq-variety-0.8.12/lib/python3.12/site-packages/variety/VarietyWindow.py", line 1084, in server_options_thread
    self.server_options = Util.fetch_json(VarietyWindow.SERVERSIDE_OPTIONS_URL)
                          ^^^^^^^^^^^^^^^^^^^^^^^^^^^^^^^^^^^^^^^^^^^^^^^^^^^^^
  File "/nix/store/xc3xswijz8h0ccdq73257z072m37phnq-variety-0.8.12/lib/python3.12/site-packages/variety/Util.py", line 684, in fetch_json
    return Util.request(url, data, **request_kwargs).json()
           ^^^^^^^^^^^^^^^^^^^^^^^^^^^^^^^^^^^^^^^^^
  File "/nix/store/xc3xswijz8h0ccdq73257z072m37phnq-variety-0.8.12/lib/python3.12/site-packages/variety/Util.py", line 654, in request
    r = requests.request(
        ^^^^^^^^^^^^^^^^^
  File "/nix/store/l4y7mm2d1dnybyym01b4032h4gji221p-python3.12-requests-2.32.3/lib/python3.12/site-packages/requests/api.py", line 59, in request
    return session.request(method=method, url=url, **kwargs)
           ^^^^^^^^^^^^^^^^^^^^^^^^^^^^^^^^^^^^^^^^^^^^^^^^^
  File "/nix/store/l4y7mm2d1dnybyym01b4032h4gji221p-python3.12-requests-2.32.3/lib/python3.12/site-packages/requests/sessions.py", line 589, in request
    resp = self.send(prep, **send_kwargs)
           ^^^^^^^^^^^^^^^^^^^^^^^^^^^^^^
  File "/nix/store/l4y7mm2d1dnybyym01b4032h4gji221p-python3.12-requests-2.32.3/lib/python3.12/site-packages/requests/sessions.py", line 703, in send
    r = adapter.send(request, **kwargs)
        ^^^^^^^^^^^^^^^^^^^^^^^^^^^^^^^
  File "/nix/store/l4y7mm2d1dnybyym01b4032h4gji221p-python3.12-requests-2.32.3/lib/python3.12/site-packages/requests/adapters.py", line 716, in send
    raise ConnectionError(e, request=request)
requests.exceptions.ConnectionError: HTTPConnectionPool(host='tiny.cc', port=80): Max retries exceeded with url: /variety-options-063 (Caused by NameResolutionError("<urllib3.connection.HTTPConnection object at 0x7fa448541dc0>: Failed to resolve 'tiny.cc' ([Errno -3] Temporary failure in name resolution)"))
INFO: 2025-01-19 23:28:59,252: server_options_thread() 'Fetching server options from http://tiny.cc/variety-options-063'
ERROR: 2025-01-19 23:28:59,260: server_options_thread() 'Could not fetch Variety serverside options'
Traceback (most recent call last):
  File "/nix/store/avkdkdhnb136l7scx4bnhjmnycfbjsl0-python3.12-urllib3-2.2.3/lib/python3.12/site-packages/urllib3/connection.py", line 199, in _new_conn
    sock = connection.create_connection(
           ^^^^^^^^^^^^^^^^^^^^^^^^^^^^^
  File "/nix/store/avkdkdhnb136l7scx4bnhjmnycfbjsl0-python3.12-urllib3-2.2.3/lib/python3.12/site-packages/urllib3/util/connection.py", line 60, in create_connection
    for res in socket.getaddrinfo(host, port, family, socket.SOCK_STREAM):
               ^^^^^^^^^^^^^^^^^^^^^^^^^^^^^^^^^^^^^^^^^^^^^^^^^^^^^^^^^^
  File "/nix/store/901c80rlps5q05bnjk1sj4zaz5k736nc-python3-3.12.7/lib/python3.12/socket.py", line 976, in getaddrinfo
    for res in _socket.getaddrinfo(host, port, family, type, proto, flags):
               ^^^^^^^^^^^^^^^^^^^^^^^^^^^^^^^^^^^^^^^^^^^^^^^^^^^^^^^^^^^
socket.gaierror: [Errno -3] Temporary failure in name resolution

The above exception was the direct cause of the following exception:

Traceback (most recent call last):
  File "/nix/store/avkdkdhnb136l7scx4bnhjmnycfbjsl0-python3.12-urllib3-2.2.3/lib/python3.12/site-packages/urllib3/connectionpool.py", line 789, in urlopen
    response = self._make_request(
               ^^^^^^^^^^^^^^^^^^^
  File "/nix/store/avkdkdhnb136l7scx4bnhjmnycfbjsl0-python3.12-urllib3-2.2.3/lib/python3.12/site-packages/urllib3/connectionpool.py", line 495, in _make_request
    conn.request(
  File "/nix/store/avkdkdhnb136l7scx4bnhjmnycfbjsl0-python3.12-urllib3-2.2.3/lib/python3.12/site-packages/urllib3/connection.py", line 441, in request
    self.endheaders()
  File "/nix/store/901c80rlps5q05bnjk1sj4zaz5k736nc-python3-3.12.7/lib/python3.12/http/client.py", line 1331, in endheaders
    self._send_output(message_body, encode_chunked=encode_chunked)
  File "/nix/store/901c80rlps5q05bnjk1sj4zaz5k736nc-python3-3.12.7/lib/python3.12/http/client.py", line 1091, in _send_output
    self.send(msg)
  File "/nix/store/901c80rlps5q05bnjk1sj4zaz5k736nc-python3-3.12.7/lib/python3.12/http/client.py", line 1035, in send
    self.connect()
  File "/nix/store/avkdkdhnb136l7scx4bnhjmnycfbjsl0-python3.12-urllib3-2.2.3/lib/python3.12/site-packages/urllib3/connection.py", line 279, in connect
    self.sock = self._new_conn()
                ^^^^^^^^^^^^^^^^
  File "/nix/store/avkdkdhnb136l7scx4bnhjmnycfbjsl0-python3.12-urllib3-2.2.3/lib/python3.12/site-packages/urllib3/connection.py", line 206, in _new_conn
    raise NameResolutionError(self.host, self, e) from e
urllib3.exceptions.NameResolutionError: <urllib3.connection.HTTPConnection object at 0x7fa4485403e0>: Failed to resolve 'tiny.cc' ([Errno -3] Temporary failure in name resolution)

The above exception was the direct cause of the following exception:

Traceback (most recent call last):
  File "/nix/store/l4y7mm2d1dnybyym01b4032h4gji221p-python3.12-requests-2.32.3/lib/python3.12/site-packages/requests/adapters.py", line 683, in send
    resp = conn.urlopen(
           ^^^^^^^^^^^^^
  File "/nix/store/avkdkdhnb136l7scx4bnhjmnycfbjsl0-python3.12-urllib3-2.2.3/lib/python3.12/site-packages/urllib3/connectionpool.py", line 843, in urlopen
    retries = retries.increment(
              ^^^^^^^^^^^^^^^^^^
  File "/nix/store/avkdkdhnb136l7scx4bnhjmnycfbjsl0-python3.12-urllib3-2.2.3/lib/python3.12/site-packages/urllib3/util/retry.py", line 519, in increment
    raise MaxRetryError(_pool, url, reason) from reason  # type: ignore[arg-type]
    ^^^^^^^^^^^^^^^^^^^^^^^^^^^^^^^^^^^^^^^^^^^^^^^^^^^
urllib3.exceptions.MaxRetryError: HTTPConnectionPool(host='tiny.cc', port=80): Max retries exceeded with url: /variety-options-063 (Caused by NameResolutionError("<urllib3.connection.HTTPConnection object at 0x7fa4485403e0>: Failed to resolve 'tiny.cc' ([Errno -3] Temporary failure in name resolution)"))

During handling of the above exception, another exception occurred:

Traceback (most recent call last):
  File "/nix/store/xc3xswijz8h0ccdq73257z072m37phnq-variety-0.8.12/lib/python3.12/site-packages/variety/VarietyWindow.py", line 1084, in server_options_thread
    self.server_options = Util.fetch_json(VarietyWindow.SERVERSIDE_OPTIONS_URL)
                          ^^^^^^^^^^^^^^^^^^^^^^^^^^^^^^^^^^^^^^^^^^^^^^^^^^^^^
  File "/nix/store/xc3xswijz8h0ccdq73257z072m37phnq-variety-0.8.12/lib/python3.12/site-packages/variety/Util.py", line 684, in fetch_json
    return Util.request(url, data, **request_kwargs).json()
           ^^^^^^^^^^^^^^^^^^^^^^^^^^^^^^^^^^^^^^^^^
  File "/nix/store/xc3xswijz8h0ccdq73257z072m37phnq-variety-0.8.12/lib/python3.12/site-packages/variety/Util.py", line 654, in request
    r = requests.request(
        ^^^^^^^^^^^^^^^^^
  File "/nix/store/l4y7mm2d1dnybyym01b4032h4gji221p-python3.12-requests-2.32.3/lib/python3.12/site-packages/requests/api.py", line 59, in request
    return session.request(method=method, url=url, **kwargs)
           ^^^^^^^^^^^^^^^^^^^^^^^^^^^^^^^^^^^^^^^^^^^^^^^^^
  File "/nix/store/l4y7mm2d1dnybyym01b4032h4gji221p-python3.12-requests-2.32.3/lib/python3.12/site-packages/requests/sessions.py", line 589, in request
    resp = self.send(prep, **send_kwargs)
           ^^^^^^^^^^^^^^^^^^^^^^^^^^^^^^
  File "/nix/store/l4y7mm2d1dnybyym01b4032h4gji221p-python3.12-requests-2.32.3/lib/python3.12/site-packages/requests/sessions.py", line 703, in send
    r = adapter.send(request, **kwargs)
        ^^^^^^^^^^^^^^^^^^^^^^^^^^^^^^^
  File "/nix/store/l4y7mm2d1dnybyym01b4032h4gji221p-python3.12-requests-2.32.3/lib/python3.12/site-packages/requests/adapters.py", line 716, in send
    raise ConnectionError(e, request=request)
requests.exceptions.ConnectionError: HTTPConnectionPool(host='tiny.cc', port=80): Max retries exceeded with url: /variety-options-063 (Caused by NameResolutionError("<urllib3.connection.HTTPConnection object at 0x7fa4485403e0>: Failed to resolve 'tiny.cc' ([Errno -3] Temporary failure in name resolution)"))
INFO: 2025-01-19 23:29:29,263: server_options_thread() 'Fetching server options from http://tiny.cc/variety-options-063'
ERROR: 2025-01-19 23:29:29,273: server_options_thread() 'Could not fetch Variety serverside options'
Traceback (most recent call last):
  File "/nix/store/avkdkdhnb136l7scx4bnhjmnycfbjsl0-python3.12-urllib3-2.2.3/lib/python3.12/site-packages/urllib3/connection.py", line 199, in _new_conn
    sock = connection.create_connection(
           ^^^^^^^^^^^^^^^^^^^^^^^^^^^^^
  File "/nix/store/avkdkdhnb136l7scx4bnhjmnycfbjsl0-python3.12-urllib3-2.2.3/lib/python3.12/site-packages/urllib3/util/connection.py", line 60, in create_connection
    for res in socket.getaddrinfo(host, port, family, socket.SOCK_STREAM):
               ^^^^^^^^^^^^^^^^^^^^^^^^^^^^^^^^^^^^^^^^^^^^^^^^^^^^^^^^^^
  File "/nix/store/901c80rlps5q05bnjk1sj4zaz5k736nc-python3-3.12.7/lib/python3.12/socket.py", line 976, in getaddrinfo
    for res in _socket.getaddrinfo(host, port, family, type, proto, flags):
               ^^^^^^^^^^^^^^^^^^^^^^^^^^^^^^^^^^^^^^^^^^^^^^^^^^^^^^^^^^^
socket.gaierror: [Errno -3] Temporary failure in name resolution

The above exception was the direct cause of the following exception:

Traceback (most recent call last):
  File "/nix/store/avkdkdhnb136l7scx4bnhjmnycfbjsl0-python3.12-urllib3-2.2.3/lib/python3.12/site-packages/urllib3/connectionpool.py", line 789, in urlopen
    response = self._make_request(
               ^^^^^^^^^^^^^^^^^^^
  File "/nix/store/avkdkdhnb136l7scx4bnhjmnycfbjsl0-python3.12-urllib3-2.2.3/lib/python3.12/site-packages/urllib3/connectionpool.py", line 495, in _make_request
    conn.request(
  File "/nix/store/avkdkdhnb136l7scx4bnhjmnycfbjsl0-python3.12-urllib3-2.2.3/lib/python3.12/site-packages/urllib3/connection.py", line 441, in request
    self.endheaders()
  File "/nix/store/901c80rlps5q05bnjk1sj4zaz5k736nc-python3-3.12.7/lib/python3.12/http/client.py", line 1331, in endheaders
    self._send_output(message_body, encode_chunked=encode_chunked)
  File "/nix/store/901c80rlps5q05bnjk1sj4zaz5k736nc-python3-3.12.7/lib/python3.12/http/client.py", line 1091, in _send_output
    self.send(msg)
  File "/nix/store/901c80rlps5q05bnjk1sj4zaz5k736nc-python3-3.12.7/lib/python3.12/http/client.py", line 1035, in send
    self.connect()
  File "/nix/store/avkdkdhnb136l7scx4bnhjmnycfbjsl0-python3.12-urllib3-2.2.3/lib/python3.12/site-packages/urllib3/connection.py", line 279, in connect
    self.sock = self._new_conn()
                ^^^^^^^^^^^^^^^^
  File "/nix/store/avkdkdhnb136l7scx4bnhjmnycfbjsl0-python3.12-urllib3-2.2.3/lib/python3.12/site-packages/urllib3/connection.py", line 206, in _new_conn
    raise NameResolutionError(self.host, self, e) from e
urllib3.exceptions.NameResolutionError: <urllib3.connection.HTTPConnection object at 0x7fa448517e90>: Failed to resolve 'tiny.cc' ([Errno -3] Temporary failure in name resolution)

The above exception was the direct cause of the following exception:

Traceback (most recent call last):
  File "/nix/store/l4y7mm2d1dnybyym01b4032h4gji221p-python3.12-requests-2.32.3/lib/python3.12/site-packages/requests/adapters.py", line 683, in send
    resp = conn.urlopen(
           ^^^^^^^^^^^^^
  File "/nix/store/avkdkdhnb136l7scx4bnhjmnycfbjsl0-python3.12-urllib3-2.2.3/lib/python3.12/site-packages/urllib3/connectionpool.py", line 843, in urlopen
    retries = retries.increment(
              ^^^^^^^^^^^^^^^^^^
  File "/nix/store/avkdkdhnb136l7scx4bnhjmnycfbjsl0-python3.12-urllib3-2.2.3/lib/python3.12/site-packages/urllib3/util/retry.py", line 519, in increment
    raise MaxRetryError(_pool, url, reason) from reason  # type: ignore[arg-type]
    ^^^^^^^^^^^^^^^^^^^^^^^^^^^^^^^^^^^^^^^^^^^^^^^^^^^
urllib3.exceptions.MaxRetryError: HTTPConnectionPool(host='tiny.cc', port=80): Max retries exceeded with url: /variety-options-063 (Caused by NameResolutionError("<urllib3.connection.HTTPConnection object at 0x7fa448517e90>: Failed to resolve 'tiny.cc' ([Errno -3] Temporary failure in name resolution)"))

During handling of the above exception, another exception occurred:

Traceback (most recent call last):
  File "/nix/store/xc3xswijz8h0ccdq73257z072m37phnq-variety-0.8.12/lib/python3.12/site-packages/variety/VarietyWindow.py", line 1084, in server_options_thread
    self.server_options = Util.fetch_json(VarietyWindow.SERVERSIDE_OPTIONS_URL)
                          ^^^^^^^^^^^^^^^^^^^^^^^^^^^^^^^^^^^^^^^^^^^^^^^^^^^^^
  File "/nix/store/xc3xswijz8h0ccdq73257z072m37phnq-variety-0.8.12/lib/python3.12/site-packages/variety/Util.py", line 684, in fetch_json
    return Util.request(url, data, **request_kwargs).json()
           ^^^^^^^^^^^^^^^^^^^^^^^^^^^^^^^^^^^^^^^^^
  File "/nix/store/xc3xswijz8h0ccdq73257z072m37phnq-variety-0.8.12/lib/python3.12/site-packages/variety/Util.py", line 654, in request
    r = requests.request(
        ^^^^^^^^^^^^^^^^^
  File "/nix/store/l4y7mm2d1dnybyym01b4032h4gji221p-python3.12-requests-2.32.3/lib/python3.12/site-packages/requests/api.py", line 59, in request
    return session.request(method=method, url=url, **kwargs)
           ^^^^^^^^^^^^^^^^^^^^^^^^^^^^^^^^^^^^^^^^^^^^^^^^^
  File "/nix/store/l4y7mm2d1dnybyym01b4032h4gji221p-python3.12-requests-2.32.3/lib/python3.12/site-packages/requests/sessions.py", line 589, in request
    resp = self.send(prep, **send_kwargs)
           ^^^^^^^^^^^^^^^^^^^^^^^^^^^^^^
  File "/nix/store/l4y7mm2d1dnybyym01b4032h4gji221p-python3.12-requests-2.32.3/lib/python3.12/site-packages/requests/sessions.py", line 703, in send
    r = adapter.send(request, **kwargs)
        ^^^^^^^^^^^^^^^^^^^^^^^^^^^^^^^
  File "/nix/store/l4y7mm2d1dnybyym01b4032h4gji221p-python3.12-requests-2.32.3/lib/python3.12/site-packages/requests/adapters.py", line 716, in send
    raise ConnectionError(e, request=request)
requests.exceptions.ConnectionError: HTTPConnectionPool(host='tiny.cc', port=80): Max retries exceeded with url: /variety-options-063 (Caused by NameResolutionError("<urllib3.connection.HTTPConnection object at 0x7fa448517e90>: Failed to resolve 'tiny.cc' ([Errno -3] Temporary failure in name resolution)"))
INFO: 2025-01-19 23:29:59,280: server_options_thread() 'Fetching server options from http://tiny.cc/variety-options-063'
ERROR: 2025-01-19 23:30:16,992: server_options_thread() 'Could not fetch Variety serverside options'
Traceback (most recent call last):
  File "/nix/store/avkdkdhnb136l7scx4bnhjmnycfbjsl0-python3.12-urllib3-2.2.3/lib/python3.12/site-packages/urllib3/connectionpool.py", line 536, in _make_request
    response = conn.getresponse()
               ^^^^^^^^^^^^^^^^^^
  File "/nix/store/avkdkdhnb136l7scx4bnhjmnycfbjsl0-python3.12-urllib3-2.2.3/lib/python3.12/site-packages/urllib3/connection.py", line 507, in getresponse
    httplib_response = super().getresponse()
                       ^^^^^^^^^^^^^^^^^^^^^
  File "/nix/store/901c80rlps5q05bnjk1sj4zaz5k736nc-python3-3.12.7/lib/python3.12/http/client.py", line 1428, in getresponse
    response.begin()
  File "/nix/store/901c80rlps5q05bnjk1sj4zaz5k736nc-python3-3.12.7/lib/python3.12/http/client.py", line 331, in begin
    version, status, reason = self._read_status()
                              ^^^^^^^^^^^^^^^^^^^
  File "/nix/store/901c80rlps5q05bnjk1sj4zaz5k736nc-python3-3.12.7/lib/python3.12/http/client.py", line 292, in _read_status
    line = str(self.fp.readline(_MAXLINE + 1), "iso-8859-1")
               ^^^^^^^^^^^^^^^^^^^^^^^^^^^^^^
  File "/nix/store/901c80rlps5q05bnjk1sj4zaz5k736nc-python3-3.12.7/lib/python3.12/socket.py", line 720, in readinto
    return self._sock.recv_into(b)
           ^^^^^^^^^^^^^^^^^^^^^^^
  File "/nix/store/901c80rlps5q05bnjk1sj4zaz5k736nc-python3-3.12.7/lib/python3.12/ssl.py", line 1251, in recv_into
    return self.read(nbytes, buffer)
           ^^^^^^^^^^^^^^^^^^^^^^^^^
  File "/nix/store/901c80rlps5q05bnjk1sj4zaz5k736nc-python3-3.12.7/lib/python3.12/ssl.py", line 1103, in read
    return self._sslobj.read(len, buffer)
           ^^^^^^^^^^^^^^^^^^^^^^^^^^^^^^
TimeoutError: The read operation timed out

The above exception was the direct cause of the following exception:

Traceback (most recent call last):
  File "/nix/store/l4y7mm2d1dnybyym01b4032h4gji221p-python3.12-requests-2.32.3/lib/python3.12/site-packages/requests/adapters.py", line 683, in send
    resp = conn.urlopen(
           ^^^^^^^^^^^^^
  File "/nix/store/avkdkdhnb136l7scx4bnhjmnycfbjsl0-python3.12-urllib3-2.2.3/lib/python3.12/site-packages/urllib3/connectionpool.py", line 843, in urlopen
    retries = retries.increment(
              ^^^^^^^^^^^^^^^^^^
  File "/nix/store/avkdkdhnb136l7scx4bnhjmnycfbjsl0-python3.12-urllib3-2.2.3/lib/python3.12/site-packages/urllib3/util/retry.py", line 474, in increment
    raise reraise(type(error), error, _stacktrace)
          ^^^^^^^^^^^^^^^^^^^^^^^^^^^^^^^^^^^^^^^^
  File "/nix/store/avkdkdhnb136l7scx4bnhjmnycfbjsl0-python3.12-urllib3-2.2.3/lib/python3.12/site-packages/urllib3/util/util.py", line 39, in reraise
    raise value
  File "/nix/store/avkdkdhnb136l7scx4bnhjmnycfbjsl0-python3.12-urllib3-2.2.3/lib/python3.12/site-packages/urllib3/connectionpool.py", line 789, in urlopen
    response = self._make_request(
               ^^^^^^^^^^^^^^^^^^^
  File "/nix/store/avkdkdhnb136l7scx4bnhjmnycfbjsl0-python3.12-urllib3-2.2.3/lib/python3.12/site-packages/urllib3/connectionpool.py", line 538, in _make_request
    self._raise_timeout(err=e, url=url, timeout_value=read_timeout)
  File "/nix/store/avkdkdhnb136l7scx4bnhjmnycfbjsl0-python3.12-urllib3-2.2.3/lib/python3.12/site-packages/urllib3/connectionpool.py", line 369, in _raise_timeout
    raise ReadTimeoutError(
urllib3.exceptions.ReadTimeoutError: HTTPSConnectionPool(host='tiny.cc', port=443): Read timed out. (read timeout=5)

During handling of the above exception, another exception occurred:

Traceback (most recent call last):
  File "/nix/store/xc3xswijz8h0ccdq73257z072m37phnq-variety-0.8.12/lib/python3.12/site-packages/variety/VarietyWindow.py", line 1084, in server_options_thread
    self.server_options = Util.fetch_json(VarietyWindow.SERVERSIDE_OPTIONS_URL)
                          ^^^^^^^^^^^^^^^^^^^^^^^^^^^^^^^^^^^^^^^^^^^^^^^^^^^^^
  File "/nix/store/xc3xswijz8h0ccdq73257z072m37phnq-variety-0.8.12/lib/python3.12/site-packages/variety/Util.py", line 684, in fetch_json
    return Util.request(url, data, **request_kwargs).json()
           ^^^^^^^^^^^^^^^^^^^^^^^^^^^^^^^^^^^^^^^^^
  File "/nix/store/xc3xswijz8h0ccdq73257z072m37phnq-variety-0.8.12/lib/python3.12/site-packages/variety/Util.py", line 654, in request
    r = requests.request(
        ^^^^^^^^^^^^^^^^^
  File "/nix/store/l4y7mm2d1dnybyym01b4032h4gji221p-python3.12-requests-2.32.3/lib/python3.12/site-packages/requests/api.py", line 59, in request
    return session.request(method=method, url=url, **kwargs)
           ^^^^^^^^^^^^^^^^^^^^^^^^^^^^^^^^^^^^^^^^^^^^^^^^^
  File "/nix/store/l4y7mm2d1dnybyym01b4032h4gji221p-python3.12-requests-2.32.3/lib/python3.12/site-packages/requests/sessions.py", line 589, in request
    resp = self.send(prep, **send_kwargs)
           ^^^^^^^^^^^^^^^^^^^^^^^^^^^^^^
  File "/nix/store/l4y7mm2d1dnybyym01b4032h4gji221p-python3.12-requests-2.32.3/lib/python3.12/site-packages/requests/sessions.py", line 724, in send
    history = [resp for resp in gen]
                                ^^^
  File "/nix/store/l4y7mm2d1dnybyym01b4032h4gji221p-python3.12-requests-2.32.3/lib/python3.12/site-packages/requests/sessions.py", line 265, in resolve_redirects
    resp = self.send(
           ^^^^^^^^^^
  File "/nix/store/l4y7mm2d1dnybyym01b4032h4gji221p-python3.12-requests-2.32.3/lib/python3.12/site-packages/requests/sessions.py", line 703, in send
    r = adapter.send(request, **kwargs)
        ^^^^^^^^^^^^^^^^^^^^^^^^^^^^^^^
  File "/nix/store/l4y7mm2d1dnybyym01b4032h4gji221p-python3.12-requests-2.32.3/lib/python3.12/site-packages/requests/adapters.py", line 729, in send
    raise ReadTimeout(e, request=request)
requests.exceptions.ReadTimeout: HTTPSConnectionPool(host='tiny.cc', port=443): Read timed out. (read timeout=5)
INFO: 2025-01-19 23:30:47,003: server_options_thread() 'Fetching server options from http://tiny.cc/variety-options-063'
ERROR: 2025-01-19 23:30:55,438: server_options_thread() 'Could not fetch Variety serverside options'
Traceback (most recent call last):
  File "/nix/store/avkdkdhnb136l7scx4bnhjmnycfbjsl0-python3.12-urllib3-2.2.3/lib/python3.12/site-packages/urllib3/connectionpool.py", line 466, in _make_request
    self._validate_conn(conn)
  File "/nix/store/avkdkdhnb136l7scx4bnhjmnycfbjsl0-python3.12-urllib3-2.2.3/lib/python3.12/site-packages/urllib3/connectionpool.py", line 1095, in _validate_conn
    conn.connect()
  File "/nix/store/avkdkdhnb136l7scx4bnhjmnycfbjsl0-python3.12-urllib3-2.2.3/lib/python3.12/site-packages/urllib3/connection.py", line 730, in connect
    sock_and_verified = _ssl_wrap_socket_and_match_hostname(
                        ^^^^^^^^^^^^^^^^^^^^^^^^^^^^^^^^^^^^
  File "/nix/store/avkdkdhnb136l7scx4bnhjmnycfbjsl0-python3.12-urllib3-2.2.3/lib/python3.12/site-packages/urllib3/connection.py", line 909, in _ssl_wrap_socket_and_match_hostname
    ssl_sock = ssl_wrap_socket(
               ^^^^^^^^^^^^^^^^
  File "/nix/store/avkdkdhnb136l7scx4bnhjmnycfbjsl0-python3.12-urllib3-2.2.3/lib/python3.12/site-packages/urllib3/util/ssl_.py", line 469, in ssl_wrap_socket
    ssl_sock = _ssl_wrap_socket_impl(sock, context, tls_in_tls, server_hostname)
               ^^^^^^^^^^^^^^^^^^^^^^^^^^^^^^^^^^^^^^^^^^^^^^^^^^^^^^^^^^^^^^^^^
  File "/nix/store/avkdkdhnb136l7scx4bnhjmnycfbjsl0-python3.12-urllib3-2.2.3/lib/python3.12/site-packages/urllib3/util/ssl_.py", line 513, in _ssl_wrap_socket_impl
    return ssl_context.wrap_socket(sock, server_hostname=server_hostname)
           ^^^^^^^^^^^^^^^^^^^^^^^^^^^^^^^^^^^^^^^^^^^^^^^^^^^^^^^^^^^^^^
  File "/nix/store/901c80rlps5q05bnjk1sj4zaz5k736nc-python3-3.12.7/lib/python3.12/ssl.py", line 455, in wrap_socket
    return self.sslsocket_class._create(
           ^^^^^^^^^^^^^^^^^^^^^^^^^^^^^
  File "/nix/store/901c80rlps5q05bnjk1sj4zaz5k736nc-python3-3.12.7/lib/python3.12/ssl.py", line 1041, in _create
    self.do_handshake()
  File "/nix/store/901c80rlps5q05bnjk1sj4zaz5k736nc-python3-3.12.7/lib/python3.12/ssl.py", line 1319, in do_handshake
    self._sslobj.do_handshake()
TimeoutError: _ssl.c:983: The handshake operation timed out

The above exception was the direct cause of the following exception:

Traceback (most recent call last):
  File "/nix/store/l4y7mm2d1dnybyym01b4032h4gji221p-python3.12-requests-2.32.3/lib/python3.12/site-packages/requests/adapters.py", line 683, in send
    resp = conn.urlopen(
           ^^^^^^^^^^^^^
  File "/nix/store/avkdkdhnb136l7scx4bnhjmnycfbjsl0-python3.12-urllib3-2.2.3/lib/python3.12/site-packages/urllib3/connectionpool.py", line 843, in urlopen
    retries = retries.increment(
              ^^^^^^^^^^^^^^^^^^
  File "/nix/store/avkdkdhnb136l7scx4bnhjmnycfbjsl0-python3.12-urllib3-2.2.3/lib/python3.12/site-packages/urllib3/util/retry.py", line 474, in increment
    raise reraise(type(error), error, _stacktrace)
          ^^^^^^^^^^^^^^^^^^^^^^^^^^^^^^^^^^^^^^^^
  File "/nix/store/avkdkdhnb136l7scx4bnhjmnycfbjsl0-python3.12-urllib3-2.2.3/lib/python3.12/site-packages/urllib3/util/util.py", line 39, in reraise
    raise value
  File "/nix/store/avkdkdhnb136l7scx4bnhjmnycfbjsl0-python3.12-urllib3-2.2.3/lib/python3.12/site-packages/urllib3/connectionpool.py", line 789, in urlopen
    response = self._make_request(
               ^^^^^^^^^^^^^^^^^^^
  File "/nix/store/avkdkdhnb136l7scx4bnhjmnycfbjsl0-python3.12-urllib3-2.2.3/lib/python3.12/site-packages/urllib3/connectionpool.py", line 490, in _make_request
    raise new_e
  File "/nix/store/avkdkdhnb136l7scx4bnhjmnycfbjsl0-python3.12-urllib3-2.2.3/lib/python3.12/site-packages/urllib3/connectionpool.py", line 468, in _make_request
    self._raise_timeout(err=e, url=url, timeout_value=conn.timeout)
  File "/nix/store/avkdkdhnb136l7scx4bnhjmnycfbjsl0-python3.12-urllib3-2.2.3/lib/python3.12/site-packages/urllib3/connectionpool.py", line 369, in _raise_timeout
    raise ReadTimeoutError(
urllib3.exceptions.ReadTimeoutError: HTTPSConnectionPool(host='tiny.cc', port=443): Read timed out. (read timeout=5)

During handling of the above exception, another exception occurred:

Traceback (most recent call last):
  File "/nix/store/xc3xswijz8h0ccdq73257z072m37phnq-variety-0.8.12/lib/python3.12/site-packages/variety/VarietyWindow.py", line 1084, in server_options_thread
    self.server_options = Util.fetch_json(VarietyWindow.SERVERSIDE_OPTIONS_URL)
                          ^^^^^^^^^^^^^^^^^^^^^^^^^^^^^^^^^^^^^^^^^^^^^^^^^^^^^
  File "/nix/store/xc3xswijz8h0ccdq73257z072m37phnq-variety-0.8.12/lib/python3.12/site-packages/variety/Util.py", line 684, in fetch_json
    return Util.request(url, data, **request_kwargs).json()
           ^^^^^^^^^^^^^^^^^^^^^^^^^^^^^^^^^^^^^^^^^
  File "/nix/store/xc3xswijz8h0ccdq73257z072m37phnq-variety-0.8.12/lib/python3.12/site-packages/variety/Util.py", line 654, in request
    r = requests.request(
        ^^^^^^^^^^^^^^^^^
  File "/nix/store/l4y7mm2d1dnybyym01b4032h4gji221p-python3.12-requests-2.32.3/lib/python3.12/site-packages/requests/api.py", line 59, in request
    return session.request(method=method, url=url, **kwargs)
           ^^^^^^^^^^^^^^^^^^^^^^^^^^^^^^^^^^^^^^^^^^^^^^^^^
  File "/nix/store/l4y7mm2d1dnybyym01b4032h4gji221p-python3.12-requests-2.32.3/lib/python3.12/site-packages/requests/sessions.py", line 589, in request
    resp = self.send(prep, **send_kwargs)
           ^^^^^^^^^^^^^^^^^^^^^^^^^^^^^^
  File "/nix/store/l4y7mm2d1dnybyym01b4032h4gji221p-python3.12-requests-2.32.3/lib/python3.12/site-packages/requests/sessions.py", line 724, in send
    history = [resp for resp in gen]
                                ^^^
  File "/nix/store/l4y7mm2d1dnybyym01b4032h4gji221p-python3.12-requests-2.32.3/lib/python3.12/site-packages/requests/sessions.py", line 265, in resolve_redirects
    resp = self.send(
           ^^^^^^^^^^
  File "/nix/store/l4y7mm2d1dnybyym01b4032h4gji221p-python3.12-requests-2.32.3/lib/python3.12/site-packages/requests/sessions.py", line 703, in send
    r = adapter.send(request, **kwargs)
        ^^^^^^^^^^^^^^^^^^^^^^^^^^^^^^^
  File "/nix/store/l4y7mm2d1dnybyym01b4032h4gji221p-python3.12-requests-2.32.3/lib/python3.12/site-packages/requests/adapters.py", line 729, in send
    raise ReadTimeout(e, request=request)
requests.exceptions.ReadTimeout: HTTPSConnectionPool(host='tiny.cc', port=443): Read timed out. (read timeout=5)
